import mcpi.minecraft as minecraft
import time
mc= minecraft.Minecraft.create()
pos=mc.player.getTilePos()
x=pos.x
y=pos.y
s=pos.z 
# mc.setBlock(x-1,y-1,s,56) цифра два
# mc.setBlock(x-2,y-1,s,56)
# mc.setBlock(x-3,y-1,s,56)
# mc.setBlock(x-4,y-1,s,56)
# mc.setBlock(x-5,y-1,s,56)
# mc.setBlock(x-5,y,s,56)
# mc.setBlock(x-4,y+1,s,56)
# mc.setBlock(x-3,y+2,s,56)
# mc.setBlock(x-2,y+3,s,56)
# mc.setBlock(x-1,y+4,s,56)
# mc.setBlock(x-1,y+5,s,56)
# mc.setBlock(x-2,y+5,s,56)
# mc.setBlock(x-3,y+5,s,56)
# mc.setBlock(x-4,y+5,s,56)
# mc.setBlock(x-5,y+5,s,56)
# 
# mc.setBlock(x-1,y-1,s,56) цифра четыри
# mc.setBlock(x-1,y-2,s,56)
# mc.setBlock(x-1,y-3,s,56)
# mc.setBlock(x-1,y-4,s,56)
# mc.setBlock(x-1,y-5,s,56)
# mc.setBlock(x-1,y-6,s,56)
# mc.setBlock(x-2,y-3,s,56)
# mc.setBlock(x-3,y-3,s,56)
# mc.setBlock(x-4,y-3,s,56)
# mc.setBlock(x-4,y-2,s,56)
# mc.setBlock(x-4,y-1,s,56)
# 
# mc.setBlock(x-1,y-1,s,56) цифра пять
# mc.setBlock(x-2,y-1,s,56)
# mc.setBlock(x-3,y-1,s,56)
# mc.setBlock(x-4,y-1,s,56)
# mc.setBlock(x-1,y,s,56)
# mc.setBlock(x-1,y+1,s,56)
# mc.setBlock(x-1,y+2,s,56)
# mc.setBlock(x-1,y+3,s,56)
# mc.setBlock(x-2,y+3,s,56)
# mc.setBlock(x-3,y+3,s,56)
# mc.setBlock(x-4,y+3,s,56)
# mc.setBlock(x-4,y+4,s,56)
# mc.setBlock(x-4,y+5,s,56)
# mc.setBlock(x-4,y+6,s,56)
# mc.setBlock(x-3,y+6,s,56)
# mc.setBlock(x-2,y+6,s,56)
# mc.setBlock(x-1,y+6,s,56)
# 
# mc.setBlock(x-1,y-1,s,56) цифра три
# mc.setBlock(x-2,y-1,s,56)
# mc.setBlock(x-3,y-1,s,56)
# mc.setBlock(x-4,y-1,s,56)
# mc.setBlock(x-1,y,s,56)
# mc.setBlock(x-1,y+1,s,56)
# mc.setBlock(x-1,y+2,s,56)
# mc.setBlock(x-1,y+3,s,56)
# mc.setBlock(x-2,y+3,s,56)
# mc.setBlock(x-3,y+3,s,56)
# mc.setBlock(x-4,y+3,s,56)
# mc.setBlock(x-1,y+4,s,56)
# mc.setBlock(x-1,y+5,s,56)
# mc.setBlock(x-1,y+6,s,56)
# mc.setBlock(x-2,y+6,s,56)
# mc.setBlock(x-3,y+6,s,56)
# mc.setBlock(x-4,y+6,s,56)
# 
# mc.setBlock(x-1,y-1,s,56) цифра семь
# mc.setBlock(x-1,y,s,56)
# mc.setBlock(x,y+1,s,56)
# mc.setBlock(x+1,y+2,s,56)
# mc.setBlock(x+2,y+3,s,56)
# mc.setBlock(x+3,y+4,s,56)
# mc.setBlock(x+3,y+5,s,56)
# mc.setBlock(x+2,y+5,s,56)
# mc.setBlock(x+1,y+5,s,56)
# mc.setBlock(x,y+5,s,56)
# mc.setBlock(x-1,y+5,s,56)
# mc.setBlock(x-2,y+5,s,56)
# mc.setBlock(x-1,y-1,s,56)
# 
# mc.setBlock(x-2,y-1,s,56) цифра шесть
# mc.setBlock(x,y-1,s,56)
# mc.setBlock(x+1,y-1,s,56)
# mc.setBlock(x+2,y-1,s,56)
# mc.setBlock(x+2,y,s,56)
# mc.setBlock(x+2,y+1,s,56)
# mc.setBlock(x+2,y+2,s,56)
# mc.setBlock(x+2,y+3,s,56)
# mc.setBlock(x-1,y+3,s,56)
# mc.setBlock(x-2,y+3,s,56)
# mc.setBlock(x,y+3,s,56)
# mc.setBlock(x+1,y+3,s,56)
# mc.setBlock(x+2,y+3,s,56)
# mc.setBlock(x-2,y+1,s,56)
# mc.setBlock(x-2,y,s,56)
# mc.setBlock(x-2,y+2,s,56)
# mc.setBlock(x-2,y+3,s,56)
# mc.setBlock(x-2,y+4,s,56)
# mc.setBlock(x-2,y+5,s,56)
# mc.setBlock(x-2,y+6,s,56)
# mc.setBlock(x-2,y+7,s,56)
# mc.setBlock(x-1,y+7,s,56)
# mc.setBlock(x,y+7,s,56)
# mc.setBlock(x+1,y+7,s,56)
# mc.setBlock(x+2,y+7,s,56)
# 
# mc.setBlock(x-1,y-1,s,56) цифра восемь
# mc.setBlock(x,y-1,s,56)
# mc.setBlock(x+1,y-1,s,56)
# mc.setBlock(x+2,y-1,s,56)
# mc.setBlock(x+3,y-1,s,56)
# mc.setBlock(x+3,y,s,56)
# mc.setBlock(x+3,y+1,s,56)
# mc.setBlock(x+3,y+2,s,56)
# mc.setBlock(x+3,y+3,s,56)
# mc.setBlock(x+2,y+3,s,56)
# mc.setBlock(x+1,y+3,s,56)
# mc.setBlock(x,y+3,s,56)
# mc.setBlock(x-1,y+3,s,56)
# mc.setBlock(x-1,y+2,s,56)
# mc.setBlock(x-1,y+1,s,56)
# mc.setBlock(x-1,y,s,56)
# mc.setBlock(x-1,y+4,s,56)
# mc.setBlock(x-1,y+5,s,56)
# mc.setBlock(x-1,y+6,s,56)
# mc.setBlock(x-1,y+7,s,56)
# mc.setBlock(x,y+7,s,56)
# mc.setBlock(x+1,y+7,s,56)
# mc.setBlock(x+2,y+7,s,56)
# mc.setBlock(x+3,y+7,s,56)
# mc.setBlock(x+3,y+6,s,56)
# mc.setBlock(x+3,y+5,s,56)
# mc.setBlock(x+3,y+4,s,56)
# 
# mc.setBlock(x-1,y-1,s,56) цифра девять
# mc.setBlock(x,y-1,s,56)
# mc.setBlock(x+1,y-1,s,56)
# mc.setBlock(x+2,y-1,s,56)
# mc.setBlock(x+3,y-1,s,56)
# mc.setBlock(x+3,y,s,56)
# mc.setBlock(x+3,y+1,s,56)
# mc.setBlock(x+3,y+2,s,56)
# mc.setBlock(x+3,y+3,s,56)
# mc.setBlock(x+2,y+3,s,56)
# mc.setBlock(x+1,y+3,s,56)
# mc.setBlock(x,y+3,s,56)
# mc.setBlock(x-1,y+3,s,56)
# mc.setBlock(x-1,y+4,s,56)
# mc.setBlock(x-1,y+5,s,56)
# mc.setBlock(x-1,y+6,s,56)
# mc.setBlock(x-1,y+7,s,56)
# mc.setBlock(x,y+7,s,56)
# mc.setBlock(x+1,y+7,s,56)
# mc.setBlock(x+2,y+7,s,56)
# mc.setBlock(x+3,y+7,s,56)
# mc.setBlock(x+3,y+6,s,56)
# mc.setBlock(x+3,y+5,s,56)
# mc.setBlock(x+3,y+4,s,56)
# 
# mc.setBlock(x-1,y-1,s,56) цифра ноль
# mc.setBlock(x,y-1,s,56)
# mc.setBlock(x+1,y-1,s,56)
# mc.setBlock(x+2,y-1,s,56)
# mc.setBlock(x+3,y-1,s,56)
# mc.setBlock(x+4,y-1,s,56)
# mc.setBlock(x+4,y,s,56)
# mc.setBlock(x+4,y+1,s,56)
# mc.setBlock(x+4,y+2,s,56)
# mc.setBlock(x+4,y+3,s,56)
# mc.setBlock(x+4,y+4,s,56)
# mc.setBlock(x+3,y+4,s,56)
# mc.setBlock(x+2,y+4,s,56)
# mc.setBlock(x+1,y+4,s,56)
# mc.setBlock(x,y+4,s,56)
# mc.setBlock(x-1,y+4,s,56)
# mc.setBlock(x-1,y+3,s,56)
# mc.setBlock(x-1,y+2,s,56)
# mc.setBlock(x-1,y+1,s,56)
# mc.setBlock(x-1,y,s,56)
# mc.setBlocks(x,y,s,x+9,y+9,s+9,1)
# mc.setBlocks(x+1,y+1,s+1,x+8,y+8,s+8,0)
# mc.setBlocks(x,y,s,x,y+8,s,4)
# mc.setBlock(x+9,y,s,4)
# mc.setBlock(x+9,y+1,s,4)
# mc.setBlock(x+9,y+2,s,4)
# mc.setBlock(x+9,y+3,s,4)
# mc.setBlock(x+9,y+4,s,4)
# mc.setBlock(x+9,y+5,s,4)
# mc.setBlock(x+9,y+6,s,4)
# mc.setBlock(x+9,y+7,s,4)
# mc.setBlock(x+9,y+8,s,4)
# dak=56
# mc.setBlock(x,y+9,s,dak)
# mc.setBlock(x+1,y+9,s,17)
# mc.setBlock(x+2,y+9,s,17)
# mc.setBlock(x+3,y+9,s,17)
# mc.setBlock(x+4,y+9,s,17)
# mc.setBlock(x+5,y+9,s,17)
# mc.setBlock(x+6,y+9,s,17)
# mc.setBlock(x+7,y+9,s,17)
# mc.setBlock(x+8,y+9,s,17)
# mc.setBlock(x+9,y+9,s,17)
# mc.setBlock(x,y+9,s+1,17)
# mc.setBlock(x+1,y+9,s+1,17)
# mc.setBlock(x+2,y+9,s+1,17)
# mc.setBlock(x+3,y+9,s+1,17)
# mc.setBlock(x+4,y+9,s+1,17)
# mc.setBlock(x+5,y+9,s+1,17)
# mc.setBlock(x+6,y+9,s+1,17)
# mc.setBlock(x+7,y+9,s+1,17)
# mc.setBlock(x+8,y+9,s+1,17)
# mc.setBlock(x+9,y+9,s+1,17)
# mc.setBlock(x,y+9,s+2,17)
# mc.setBlock(x+1,y+9,s+2,17)
# mc.setBlock(x+2,y+9,s+2,17)
# mc.setBlock(x+3,y+9,s+2,17)
# mc.setBlock(x+4,y+9,s+2,17)
# mc.setBlock(x+5,y+9,s+2,17)
# mc.setBlock(x+6,y+9,s+2,17)
# mc.setBlock(x+7,y+9,s+2,17)
# mc.setBlock(x+8,y+9,s+2,17)
# mc.setBlock(x+9,y+9,s+2,17)
# mc.setBlock(x,y+9,s+3,17)
# mc.setBlock(x+1,y+9,s+3,17)
# mc.setBlock(x+2,y+9,s+3,17)
# mc.setBlock(x+3,y+9,s+3,17)
# mc.setBlock(x+4,y+9,s+3,17)
# mc.setBlock(x+5,y+9,s+3,17)
# mc.setBlock(x+6,y+9,s+3,17)
# mc.setBlock(x+7,y+9,s+3,17)
# mc.setBlock(x+8,y+9,s+3,17)
# mc.setBlock(x+9,y+9,s+3,17)
# mc.setBlock(x+9,y,s,4)
# mc.setBlock(x+9,y+1,s,4)
# mc.setBlock(x+9,y+2,s,4)
# mc.setBlock(x+9,y+3,s,4)
# mc.setBlock(x+9,y+4,s,4)
# mc.setBlock(x+9,y+5,s,4)
# mc.setBlock(x,y+9,s+4,dak)
# mc.setBlock(x+1,y+9,s+4,dak)
# mc.setBlock(x+2,y+9,s+4,dak)
# mc.setBlock(x+3,y+9,s+4,dak)
# mc.setBlock(x+4,y+9,s+4,dak)
# mc.setBlock(x+5,y+9,s+4,dak)
# mc.setBlock(x+6,y+9,s+4,dak)
# mc.setBlock(x+7,y+9,s+4,dak)
# mc.setBlock(x+8,y+9,s+4,dak)
# mc.setBlock(x+9,y+9,s+4,dak)
# mc.setBlock(x,y+9,s+5,dak)
# mc.setBlock(x+1,y+9,s+5,dak)
# mc.setBlock(x+2,y+9,s+5,dak)
# mc.setBlock(x+3,y+9,s+5,dak)
# mc.setBlock(x+4,y+9,s+5,dak)
# mc.setBlock(x+5,y+9,s+5,dak)
# mc.setBlock(x+6,y+9,s+5,dak)
# mc.setBlock(x+7,y+9,s+5,dak)
# mc.setBlock(x+8,y+9,s+5,dak)
# mc.setBlock(x+9,y+9,s+5,dak)
# mc.setBlock(x,y+9,s+6,dak)
# mc.setBlock(x+1,y+9,s+6,dak)
# mc.setBlock(x+2,y+9,s+6,dak)
# mc.setBlock(x+3,y+9,s+6,dak)
# mc.setBlock(x+4,y+9,s+6,dak)
# mc.setBlock(x+5,y+9,s+6,dak)
# mc.setBlock(x+6,y+9,s+6,dak)
# mc.setBlock(x+7,y+9,s+6,dak)
# mc.setBlock(x+8,y+9,s+6,dak)
# mc.setBlock(x+9,y+9,s+6,dak)
# mc.setBlock(x,y+9,s+7,dak)
# mc.setBlock(x+1,y+9,s+7,dak)
# mc.setBlock(x+2,y+9,s+7,dak)
# mc.setBlock(x+3,y+9,s+7,dak)
# mc.setBlock(x+4,y+9,s+7,dak)
# mc.setBlock(x+5,y+9,s+7,dak)
# mc.setBlock(x+6,y+9,s+7,dak)
# mc.setBlock(x+7,y+9,s+7,dak)
# mc.setBlock(x+8,y+9,s+7,dak)
# mc.setBlock(x+9,y+9,s+7,dak)
# mc.setBlock(x,y+9,s+8,dak)
# mc.setBlock(x+1,y+9,s+8,dak)
# mc.setBlock(x+2,y+9,s+8,dak)
# mc.setBlock(x+3,y+9,s+8,dak)
# mc.setBlock(x+4,y+9,s+8,dak)
# mc.setBlock(x+5,y+9,s+8,dak)
# mc.setBlock(x+6,y+9,s+8,dak)
# mc.setBlock(x+7,y+9,s+8,dak)
# mc.setBlock(x+8,y+9,s+8,dak)
# mc.setBlock(x+9,y+9,s+8,dak)
# mc.setBlock(x,y+9,s+9,dak)
# mc.setBlock(x+1,y+9,s+9,dak)
# mc.setBlock(x+2,y+9,s+9,dak)
# mc.setBlock(x+3,y+9,s+9,dak)
# mc.setBlock(x+4,y+9,s+9,dak)
# mc.setBlock(x+5,y+9,s+9,dak)
# mc.setBlock(x+6,y+9,s+9,dak)
# mc.setBlock(x+7,y+9,s+9,dak)
# mc.setBlock(x+8,y+9,s+9,dak)
# mc.setBlock(x+9,y+9,s+9,dak)
# mc.setBlock(x+5,y+1,s,0)
# mc.setBlock(x+4,y+1,s,0)
# mc.setBlock(x+4,y+2,s,0)
# mc.setBlock(x+5,y+2,s,0)
# mc.setBlock(x+4,y+3,s,0)
# mc.setBlock(x+5,y+3,s,0)
# mc.setBlocks(x+8,y+1,s+8,x+1,y+1,s+1,171,14)
mc.setBlock(x-1,y,s,251,15)
mc.setBlock(x-2,y,s,251)
mc.setBlock(x-3,y,s,251,15)
mc.setBlock(x-4,y,s,251)
mc.setBlock(x-5,y,s,251,15)
mc.setBlock(x-6,y,s,251)
mc.setBlock(x-7,y,s,251,15)
mc.setBlock(x-8,y,s,251)
mc.setBlock(x-1,y,s+1,251)
mc.setBlock(x-2,y,s+1,251,15)
mc.setBlock(x-3,y,s+1,251)
mc.setBlock(x-4,y,s+1,251,15)
mc.setBlock(x-5,y,s+1,251)
mc.setBlock(x-6,y,s+1,251,15)
mc.setBlock(x-7,y,s+1,251)
mc.setBlock(x-8,y,s+1,251,15)
mc.setBlock(x-1,y,s+2,251,15)
mc.setBlock(x-2,y,s+2,251)
mc.setBlock(x-3,y,s+2,251,15)
mc.setBlock(x-4,y,s+2,251)
mc.setBlock(x-5,y,s+2,251,15)
mc.setBlock(x-6,y,s+2,251)
mc.setBlock(x-7,y,s+2,251,15)
mc.setBlock(x-8,y,s+2,251)
mc.setBlock(x-1,y,s+3,251)
mc.setBlock(x-2,y,s+3,251,15)
mc.setBlock(x-3,y,s+3,251)
mc.setBlock(x-4,y,s+3,251,15)
mc.setBlock(x-5,y,s+3,251)
mc.setBlock(x-6,y,s+3,251,15)
mc.setBlock(x-7,y,s+3,251)
mc.setBlock(x-8,y,s+3,251,15)
mc.setBlock(x-1,y,s+4,251,15)
mc.setBlock(x-2,y,s+4,251)
mc.setBlock(x-3,y,s+4,251,15)
mc.setBlock(x-4,y,s+4,251)
mc.setBlock(x-5,y,s+4,251,15)
mc.setBlock(x-6,y,s+4,251)
mc.setBlock(x-7,y,s+4,251,15)
mc.setBlock(x-8,y,s+4,251)
mc.setBlock(x-1,y,s+5,251)
mc.setBlock(x-2,y,s+5,251,15)
mc.setBlock(x-3,y,s+5,251)
mc.setBlock(x-4,y,s+5,251,15)
mc.setBlock(x-5,y,s+5,251)
mc.setBlock(x-6,y,s+5,251,15)
mc.setBlock(x-7,y,s+5,251)
mc.setBlock(x-8,y,s+5,251,15)
mc.setBlock(x-1,y,s+6,251,15)
mc.setBlock(x-2,y,s+6,251)
mc.setBlock(x-3,y,s+6,251,15)
mc.setBlock(x-4,y,s+6,251)
mc.setBlock(x-5,y,s+6,251,15)
mc.setBlock(x-6,y,s+6,251)
mc.setBlock(x-7,y,s+6,251,15)
mc.setBlock(x-8,y,s+6,251)
mc.setBlock(x-1,y,s+7,251)
mc.setBlock(x-2,y,s+7,251,15)
mc.setBlock(x-3,y,s+7,251)
mc.setBlock(x-4,y,s+7,251,15)
mc.setBlock(x-5,y,s+7,251)
mc.setBlock(x-6,y,s+7,251,15)
mc.setBlock(x-7,y,s+7,251)
mc.setBlock(x-8,y,s+7,251,15)