import random
import mcpi.minecraft as minecraft
import time
mc= minecraft.Minecraft.create()
pos=mc.player.getTilePos()
print(pos)
x=-435
y=0
z=-499
# mc.setBlock(x+1,y+4,z+5,1)
# mc.setBlock(x,y+4,z+5,1)
# mc.setBlock(x-1,y+4,z+5,1)
# mc.setBlock(x-2,y+4,z+5,1)
# mc.setBlock(x-3,y+4,z+5,1)
# mc.setBlock(x-4,y+4,z+5,1)
# mc.setBlock(x+1,y+5,z+5,56)
# mc.setBlock(x+1,y+6,z+5,56)
# mc.setBlock(x+1,y+7,z+5,56)
# mc.setBlock(x+1,y+8,z+5,56)
# mc.setBlock(x+1,y+9,z+5,56)
# mc.setBlock(x-4,y+5,z+5,1)
# mc.setBlock(x-4,y+6,z+5,1)
# mc.setBlock(x-4,y+7,z+5,1)
# mc.setBlock(x-4,y+8,z+5,1)
# mc.setBlock(x-4,y+9,z+5,1)
# mc.setBlock(x+1,y+4,z+6,1)
# mc.setBlock(x+1,y+4,z+7,1)
# mc.setBlock(x+1,y+4,z+8,1)
# mc.setBlock(x+1,y+4,z+9,1)
# mc.setBlock(x+1,y+4,z+10,41)
# mc.setBlock(x+1,y+5,z+10,41)
# mc.setBlock(x+1,y+6,z+10,41)
# mc.setBlock(x+1,y+7,z+10,41)
# mc.setBlock(x+1,y+8,z+10,41)
# mc.setBlock(x+1,y+9,z+10,41)
# mc.setBlock(x,y+4,z+10,1)
# mc.setBlock(x-1,y+4,z+10,1)
# mc.setBlock(x-2,y+4,z+10,1)
# mc.setBlock(x-3,y+4,z+10,1)
# mc.setBlock(x-4,y+4,z+10,1)
# mc.setBlock(x-4,y+5,z+10,1)
# mc.setBlock(x-4,y+6,z+10,1)
# mc.setBlock(x-4,y+7,z+10,1)
# mc.setBlock(x-4,y+8,z+10,1)
# mc.setBlock(x-4,y+9,z+10,1)
# mc.setBlock(x-4,y+4,z+9,1)
# mc.setBlock(x-4,y+4,z+8,1)
# mc.setBlock(x-4,y+4,z+7,1)
# mc.setBlock(x-4,y+4,z+6,1)
# mc.setBlocks(x,y+4,z+6,x-3,y+4,z+9,1)
# mc.setBlock(x,y+9,z+5,1)
# mc.setBlock(x-1,y+9,z+5,1)
# mc.setBlock(x-2,y+9,z+5,1)
# mc.setBlock(x-3,y+9,z+5,1)
# mc.setBlock(x-4,y+9,z+7,1)
# mc.setBlock(x-4,y+9,z+8,1)
# mc.setBlock(x-4,y+9,z+9,1)
# mc.setBlock(x-3,y+9,z+10,1)
# mc.setBlock(x-2,y+9,z+10,1)
# mc.setBlock(x-1,y+9,z+10,1)
# mc.setBlock(x,y+9,z+10,1)
# mc.setBlock(x+1,y+9,z+6,1)
# mc.setBlock(x+1,y+9,z+7,1)
# mc.setBlock(x+1,y+9,z+8,1)
# mc.setBlock(x+1,y+9,z+9,1)
# mc.setBlocks(x,y+9,z+6,x-3,y+9,z+9,1)
# mc.setBlock(x+1,y+10,z+5,1)
# mc.setBlock(x+1,y+11,z+6,1)
# mc.setBlock(x+1,y+12,z+7,1)
# mc.setBlock(x+1,y+12,z+8,1)
# mc.setBlock(x+1,y+11,z+9,1)
# mc.setBlock(x+1,y+10,z+10,1)
# mc.setBlock(x,y+12,z+8,1)
# mc.setBlock(x,y+12,z+7,1)
# mc.setBlock(x-1,y+12,z+7,1)
# mc.setBlock(x-1,y+12,z+8,1)
# mc.setBlock(x-2,y+12,z+8,1)
# mc.setBlock(x-2,y+12,z+7,1)
# mc.setBlock(x-3,y+12,z+7,1)
# mc.setBlock(x-3,y+12,z+8,1)
# mc.setBlock(x-4,y+10,z+10,1)
# mc.setBlock(x-1,y+5,z+7,41)
# mc.setBlock(x-2,y+5,z+7,41)
# mc.setBlock(x-2,y+5,z+8,41)
# mc.setBlock(x-1,y+5,z+8,41)
# mc.setBlocks(x,y+6,z+6,x-3,y+7,z+6,20)
# mc.setBlocks(x-3,y+6,z+6,x-3,y+7,z+9,20)
# mc.setBlocks(x-3,y+6,z+9,x,y+7,z+9,20)
# mc.setBlocks(x,y+6,z+9,x,y+7,z+6,20)
# mc.setBlock(x-1,y+8,z+7,41)
# mc.setBlock(x-2,y+8,z+7,41)
# mc.setBlock(x-2,y+8,z+8,41)
# mc.setBlock(x-1,y+8,z+8,41)
# mc.setBlock(x-1,y+7,z+8,10)
# mc.setBlock(x-2,y+7,z+8,10)
# mc.setBlock(x-2,y+7,z+7,10)
# mc.setBlock(x-1,y+7,z+7,10)
# def stair(x):
#     # mc.setBlock(x,y-1,z,41)
#     # mc.setBlock(x,y,z+1,41)
#     # mc.setBlock(x,y+1,z+2,41)
#     # mc.setBlock(x,y+2,z+3,41)
#     # mc.setBlock(x,y+3,z+4,41)
#     for i in range(5):
#         mc.setBlock(x,y-1+i,z+i,1)
# stair(x+1)
# stair(x-4)
# def stair2(x):
#     for i in range(5):
#         mc.setBlock(x,y+3-i,z+11+i,1)
#     # mc.setBlock(x+1,y+3,z+11,41)
#     # mc.setBlock(x+1,y+2,z+12,41)
#     # mc.setBlock(x+1,y+1,z+13,41)
#     # mc.setBlock(x+1,y,z+14,41)
#     # mc.setBlock(x+1,y-1,z+15,41)
# stair2(x+1)
# stair2(x-4)
# for i in range(6):
#     mc.setBlock(x+1,y+4+i,z+10,1)
# mc.setBlock(x+1,y+4,z+10,41)
# mc.setBlock(x+1,y+5,z+10,41)
# mc.setBlock(x+1,y+6,z+10,41)
# mc.setBlock(x+1,y+7,z+10,41)
# mc.setBlock(x+1,y+8,z+10,41)
# mc.setBlock(x+1,y+9,z+10,41)

# for i in range(5):
#     mc.setBlock(x+1,y+i+5,z+5,1)
# #     mc.setBlock(x+1,y+5,z+5,56)
# # mc.setBlock(x+1,y+6,z+5,56)
# # mc.setBlock(x+1,y+7,z+5,56)
# # mc.setBlock(x+1,y+8,z+5,56)
# # mc.setBlock(x+1,y+9,z+5,56)

# mc.setBlocks(x+1,y+5,z+5,x+1,y+9,z+5,41)

mc.setBlocks(x,y,z,x,y+16,z,97,2)
mc.setBlocks(x+5,y,z,x+5,y+16,z,97,2)
mc.setBlocks(x,y+6,z,x+5,y+6,z+29,97,2)
mc.setBlocks(x,y+16,z+29,x,y,z+29,97,2)
mc.setBlocks(x+5,y,z+29,x+5,y+16,z+29,97,2)

mc.setBlock(x,y+6,z-1,35,14)
mc.setBlock(x+1,y+6,z-1,35,14)
mc.setBlock(x+2,y+6,z-1,35,14)
mc.setBlock(x+3,y+6,z-1,35,14)
mc.setBlock(x+4,y+6,z-1,35,14)
mc.setBlock(x+5,y+6,z-1,35,14)

mc.setBlock(x,y+5,z-2,35,14)
mc.setBlock(x+1,y+5,z-2,35,14)
mc.setBlock(x+2,y+5,z-2,35,14)
mc.setBlock(x+3,y+5,z-2,35,14)
mc.setBlock(x+4,y+5,z-2,35,14)
mc.setBlock(x+5,y+5,z-2,35,14)

mc.setBlock(x,y+4,z-3,35,14)
mc.setBlock(x+1,y+4,z-3,35,14)
mc.setBlock(x+2,y+4,z-3,35,14)
mc.setBlock(x+3,y+4,z-3,35,14)
mc.setBlock(x+4,y+4,z-3,35,14)
mc.setBlock(x+5,y+4,z-3,35,14)

mc.setBlock(x,y+3,z-4,35,14)
mc.setBlock(x+1,y+3,z-4,35,14)
mc.setBlock(x+2,y+3,z-4,35,14)
mc.setBlock(x+3,y+3,z-4,35,14)
mc.setBlock(x+4,y+3,z-4,35,14)
mc.setBlock(x+5,y+3,z-4,35,14)

mc.setBlock(x,y+2,z-5,35,14)
mc.setBlock(x+1,y+2,z-5,35,14)
mc.setBlock(x+2,y+2,z-5,35,14)
mc.setBlock(x+3,y+2,z-5,35,14)
mc.setBlock(x+4,y+2,z-5,35,14)
mc.setBlock(x+5,y+2,z-5,35,14)

mc.setBlock(x,y+6,z+30,35,14)
mc.setBlock(x+1,y+6,z+30,35,14)
mc.setBlock(x+2,y+6,z+30,35,14)
mc.setBlock(x+3,y+6,z+30,35,14)
mc.setBlock(x+4,y+6,z+30,35,14)
mc.setBlock(x+5,y+6,z+30,35,14)

mc.setBlock(x,y+5,z+31,35,14)
mc.setBlock(x+1,y+5,z+31,35,14)
mc.setBlock(x+2,y+5,z+31,35,14)
mc.setBlock(x+3,y+5,z+31,35,14)
mc.setBlock(x+4,y+5,z+31,35,14)
mc.setBlock(x+5,y+5,z+31,35,14)

mc.setBlock(x,y+4,z+32,35,14)
mc.setBlock(x+1,y+4,z+32,35,14)
mc.setBlock(x+2,y+4,z+32,35,14)
mc.setBlock(x+3,y+4,z+32,35,14)
mc.setBlock(x+4,y+4,z+32,35,14)
mc.setBlock(x+5,y+4,z+32,35,14)

mc.setBlock(x,y+3,z+33,35,14)
mc.setBlock(x+1,y+3,z+33,35,14)
mc.setBlock(x+2,y+3,z+33,35,14)
mc.setBlock(x+3,y+3,z+33,35,14)
mc.setBlock(x+4,y+3,z+33,35,14)
mc.setBlock(x+5,y+3,z+33,35,14)

mc.setBlock(x,y+2,z+34,35,14)
mc.setBlock(x+1,y+2,z+34,35,14)
mc.setBlock(x+2,y+2,z+34,35,14)
mc.setBlock(x+3,y+2,z+34,35,14)
mc.setBlock(x+4,y+2,z+34,35,14)
mc.setBlock(x+5,y+2,z+34,35,14)

mc.setBlocks(x,y+7,z+8,x,y+16,z+8,97,2)
mc.setBlocks(x,y+16,z+16,x,y+7,z+16,97,2)

mc.setBlocks(x+5,y+7,z+8,x+5,y+16,z+8,97,2)
mc.setBlocks(x+5,y+7,z+16,x+5,y+16,z+16,97,2)

mc.setBlocks(x,y+7,z+4,x,y+11,z+4,45)
mc.setBlocks(x,y+7,z+12,x,y+11,z+12,45)

mc.setBlocks(x,y+7,z+22,x,y+16,z+22,97,2)
mc.setBlocks(x+5,y+7,z+22,x+5,y+16,z+22,97,2)

mc.setBlocks(x,y+7,z+19,x,y+11,z+19,45)
mc.setBlocks(x,y+7,z+26,x,y+11,z+26,45)

mc.setBlocks(x+5,y+7,z+4,x+5,y+11,z+4,45)
mc.setBlocks(x+5,y+7,z+12,x+5,y+11,z+12,45)
mc.setBlocks(x+5,y+7,z+19,x+5,y+11,z+19,45)
mc.setBlocks(x+5,y+7,z+26,x+5,y+11,z+26,45)

mc.setBlock(x+5,y+1,z-8,251,3)
mc.setBlock(x+5,y+2,z-7,251,3)
mc.setBlock(x+5,y+3,z-7,251,3)
mc.setBlock(x+5,y+4,z-6,251,3)
mc.setBlock(x+5,y+5,z-6,251,3)
mc.setBlock(x+5,y+6,z-5,251,3)
mc.setBlock(x+5,y+7,z-5,251,3)
mc.setBlock(x+5,y+8,z-4,251,3)
mc.setBlock(x+5,y+9,z-4,251,3)
mc.setBlock(x+5,y+10,z-3,251,3)
mc.setBlock(x+5,y+11,z-3,251,3)
mc.setBlock(x+5,y+12,z-2,251,3)
mc.setBlock(x+5,y+13,z-2,251,3)
mc.setBlock(x+5,y+14,z-1,251,3)
mc.setBlock(x+5,y+15,z-1,251,3)
mc.setBlock(x+5,y+16,z,251,3)
mc.setBlock(x+5,y+15,z+1,251,3)
mc.setBlock(x+5,y+14,z+2,251,3)
mc.setBlock(x+5,y+13,z+3,251,3)
mc.setBlock(x+5,y+12,z+4,251,3)
mc.setBlock(x+5,y+13,z+5,251,3)
mc.setBlock(x+5,y+14,z+6,251,3)
mc.setBlock(x+5,y+15,z+7,251,3)
mc.setBlock(x+5,y+16,z+8,251,3)
mc.setBlock(x+5,y+15,z+9,251,3)
mc.setBlock(x+5,y+14,z+10,251,3)
mc.setBlock(x+5,y+13,z+11,251,3)
mc.setBlock(x+5,y+12,z+12,251,3)
mc.setBlock(x+5,y+13,z+13,251,3)
mc.setBlock(x+5,y+14,z+14,251,3)
mc.setBlock(x+5,y+15,z+15,251,3)
mc.setBlock(x+5,y+16,z+16,251,3)
mc.setBlock(x+5,y+15,z+17,251,3)
mc.setBlock(x+5,y+14,z+17,251,3)
mc.setBlock(x+5,y+13,z+18,251,3)
mc.setBlock(x+5,y+12,z+19,251,3)
mc.setBlock(x+5,y+13,z+20,251,3)
mc.setBlock(x+5,y+14,z+21,251,3)
mc.setBlock(x+5,y+15,z+21,251,3)
mc.setBlock(x+5,y+16,z+22,251,3)
mc.setBlock(x+5,y+15,z+23,251,3)
mc.setBlock(x+5,y+14,z+24,251,3)
mc.setBlock(x+5,y+13,z+25,251,3)
mc.setBlock(x+5,y+12,z+26,251,3)
mc.setBlock(x+5,y+13,z+27,251,3)
mc.setBlock(x+5,y+14,z+28,251,3)
mc.setBlock(x+5,y+15,z+28,251,3)
mc.setBlock(x+5,y+16,z+29,251,3)

mc.setBlock(x,y+1,z-8,251,3)
mc.setBlock(x,y+2,z-7,251,3)
mc.setBlock(x,y+3,z-7,251,3)
mc.setBlock(x,y+4,z-6,251,3)
mc.setBlock(x,y+5,z-6,251,3)
mc.setBlock(x,y+6,z-5,251,3)
mc.setBlock(x,y+7,z-5,251,3)
mc.setBlock(x,y+8,z-4,251,3)
mc.setBlock(x,y+9,z-4,251,3)
mc.setBlock(x,y+10,z-3,251,3)
mc.setBlock(x,y+11,z-3,251,3)
mc.setBlock(x,y+12,z-2,251,3)
mc.setBlock(x,y+13,z-2,251,3)
mc.setBlock(x,y+14,z-1,251,3)
mc.setBlock(x,y+15,z-1,251,3)
mc.setBlock(x,y+16,z,251,3)
mc.setBlock(x,y+15,z+1,251,3)
mc.setBlock(x,y+14,z+2,251,3)
mc.setBlock(x,y+13,z+3,251,3)
mc.setBlock(x,y+12,z+4,251,3)
mc.setBlock(x,y+13,z+5,251,3)
mc.setBlock(x,y+14,z+6,251,3)
mc.setBlock(x,y+15,z+7,251,3)
mc.setBlock(x,y+16,z+8,251,3)
mc.setBlock(x,y+15,z+9,251,3)
mc.setBlock(x,y+14,z+10,251,3)
mc.setBlock(x,y+13,z+11,251,3)
mc.setBlock(x,y+12,z+12,251,3)
mc.setBlock(x,y+13,z+13,251,3)
mc.setBlock(x,y+14,z+14,251,3)
mc.setBlock(x,y+15,z+15,251,3)
mc.setBlock(x,y+16,z+16,251,3)
mc.setBlock(x,y+15,z+17,251,3)
mc.setBlock(x,y+14,z+17,251,3)
mc.setBlock(x,y+13,z+18,251,3)
mc.setBlock(x,y+12,z+19,251,3)
mc.setBlock(x,y+13,z+20,251,3)
mc.setBlock(x,y+14,z+21,251,3)
mc.setBlock(x,y+15,z+21,251,3)
mc.setBlock(x,y+16,z+22,251,3)
mc.setBlock(x,y+15,z+23,251,3)
mc.setBlock(x,y+14,z+24,251,3)
mc.setBlock(x,y+13,z+25,251,3)
mc.setBlock(x,y+12,z+26,251,3)
mc.setBlock(x,y+13,z+27,251,3)
mc.setBlock(x,y+14,z+28,251,3)
mc.setBlock(x,y+15,z+28,251,3)
mc.setBlock(x,y+16,z+29,251,3)